Workbook

Sheet EMPIEZA_AQUI
A1: SIIP · CALCULADORA PRÁCTICA DE LOS 7 INDICADORES WEB
A3: ¿QUÉ TENGO QUE HACER? | E3: COLORES
A5: 1 | B5: Abre la hoja CALCULADORA_7. | C5: Ahí están los 7 indicadores de la página web. | E5: AMARILLO | F5: Tú escribes aquí
A6: 2 | B6: Escribe únicamente en las celdas AMARILLAS. | C6: Captura el valor actual, el valor que considerarías MUY BUENO y el valor que considerarías MUY MALO. | E6: AZUL | F6: Fórmula automática
A7: 3 | B7: No escribas fórmulas. | C7: Excel calcula automáticamente un puntaje de 0 a 100. | E7: VERDE | F7: Resultado favorable
A8: 4 | B8: Mira el RESULTADO FINAL. | C8: Se pinta con color y aparece un mensaje que te dice cómo interpretarlo. | E8: AMARILLO | F8: Resultado medio
A9: 5 | B9: En SAM 2025 y SAM 2030 captura los rangos de los tres proxies. | C9: Excel calcula el rango combinado, punto medio y crecimiento anual. | E9: NARANJA | F9: Resultado bajo
E10: ROJO | F10: Atención prioritaria
A12: ¿CÓMO INTERPRETAR EL PUNTAJE 0–100?
A14: 0–39 | B14: ATENCIÓN PRIORITARIA | C14: El indicador presenta condiciones débiles. Conviene revisar los subindicadores con menor puntaje y definir acciones de mejora.
A15: 40–59 | B15: NIVEL BAJO / EN DESARROLLO | C15: Existen avances, pero todavía hay brechas importantes antes de considerar el resultado favorable.
A16: 60–79 | B16: NIVEL MEDIO / FAVORABLE CON ÁREAS DE MEJORA | C16: El indicador muestra una situación aceptable, aunque algunos componentes todavía pueden fortalecerse.
A17: 80–100 | B17: NIVEL ALTO / FAVORABLE | C17: El indicador muestra condiciones sólidas respecto a los valores de referencia que capturaste.
A19: IMPORTANTE: Los colores y rangos 0–39, 40–59, 60–79 y 80–100 son una PROPUESTA OPERATIVA DE LECTURA para facilitar la interpretación. No sustituyen los umbrales oficiales del proyecto. Lo importante es que tú defines los valores 'Muy bueno' y 'Muy malo' con base en la metodología y las fuentes del SIIP.

Sheet CALCULADORA_7
A1: CALCULADORA SIMPLE · 7 INDICADORES DE LA PÁGINA WEB
A2: AMARILLO = tú capturas | AZUL = Excel calcula | El resultado final se pinta solo y te da un mensaje.
A4: WEB-01 · PERTINENCIA SOSTENIBLE
A5: ¿PARA QUÉ SIRVE? Resume qué tan favorable es el desempeño en energía, certificaciones, eficiencia, emisiones y agua.
A7: Código | B7: Subindicador | C7: Dirección | D7: VALOR ACTUAL | E7: MUY MALO | F7: MUY BUENO | G7: PUNTAJE 0–100 | H7: Peso % | I7: Aporte | J7: ¿Qué significa? | K7: Fórmula
A8: PSO1 | B8: % energía renovable | C8: Más es mejor | D8: 100 | E8: 0 | F8: 100 | G8: =IF(OR(D8="",E8="",F8=""),"",IF(E8=F8,"",IF(C8="Más es mejor",MAX(0,MIN(100,(D8-E8)/(F8-E8)*100)),MAX(0,MIN(100,(E8-D8)/(E8-F8)*100))))) -> 100 | H8: 20 | I8: =IF(OR(G8="",H8=""),"",G8*H8/100) -> 20 | J8: Más energía renovable mejora el desempeño sostenible. | K8: 'Más es mejor: (Actual−Muy malo)/(Muy bueno−Muy malo)×100 | Menos es mejor: (Muy malo−Actual)/(Muy malo−Muy bueno)×100
A9: PSO2 | B9: Certificaciones LEED/ICREA | C9: Más es mejor | D9: 1500 | E9: 0 | F9: 100 | G9: =IF(OR(D9="",E9="",F9=""),"",IF(E9=F9,"",IF(C9="Más es mejor",MAX(0,MIN(100,(D9-E9)/(F9-E9)*100)),MAX(0,MIN(100,(E9-D9)/(E9-F9)*100))))) -> 100 | H9: 20 | I9: =IF(OR(G9="",H9=""),"",G9*H9/100) -> 20 | J9: Más instalaciones certificadas fortalecen el desempeño. | K9: 'Más es mejor: (Actual−Muy malo)/(Muy bueno−Muy malo)×100 | Menos es mejor: (Muy malo−Actual)/(Muy malo−Muy bueno)×100
A10: PSO3 | B10: Consumo energético por MW | C10: Menos es mejor | D10: 13232 | E10: 100 | F10: 0 | G10: =IF(OR(D10="",E10="",F10=""),"",IF(E10=F10,"",IF(C10="Más es mejor",MAX(0,MIN(100,(D10-E10)/(F10-E10)*100)),MAX(0,MIN(100,(E10-D10)/(E10-F10)*100))))) -> 0 | H10: 20 | I10: =IF(OR(G10="",H10=""),"",G10*H10/100) -> 0 | J10: Menor consumo por unidad de capacidad implica mejor eficiencia. | K10: 'Más es mejor: (Actual−Muy malo)/(Muy bueno−Muy malo)×100 | Menos es mejor: (Muy malo−Actual)/(Muy malo−Muy bueno)×100
A11: PSO4 | B11: Huella ambiental / emisiones | C11: Menos es mejor | D11: 80 | E11: 100 | F11: 0 | G11: =IF(OR(D11="",E11="",F11=""),"",IF(E11=F11,"",IF(C11="Más es mejor",MAX(0,MIN(100,(D11-E11)/(F11-E11)*100)),MAX(0,MIN(100,(E11-D11)/(E11-F11)*100))))) -> 20 | H11: 20 | I11: =IF(OR(G11="",H11=""),"",G11*H11/100) -> 4 | J11: Menores emisiones o huella representan mejor desempeño. | K11: 'Más es mejor: (Actual−Muy malo)/(Muy bueno−Muy malo)×100 | Menos es mejor: (Muy malo−Actual)/(Muy malo−Muy bueno)×100
A12: PSO5 | B12: Gestión hídrica / reúso | C12: Más es mejor | D12: 1200 | E12: 0 | F12: 100 | G12: =IF(OR(D12="",E12="",F12=""),"",IF(E12=F12,"",IF(C12="Más es mejor",MAX(0,MIN(100,(D12-E12)/(F12-E12)*100)),MAX(0,MIN(100,(E12-D12)/(E12-F12)*100))))) -> 100 | H12: 20 | I12: =IF(OR(G12="",H12=""),"",G12*H12/100) -> 20 | J12: Mayor reúso/tratamiento representa mejor gestión del agua. | K12: 'Más es mejor: (Actual−Muy malo)/(Muy bueno−Muy malo)×100 | Menos es mejor: (Muy malo−Actual)/(Muy malo−Muy bueno)×100
A14: RESULTADO FINAL | D14: =IF(COUNT(G8:G12)=0,"",SUM(I8:I12)/(SUM(H8:H12)/100)) -> 64 | F14: =IF(D14="","CAPTURA LOS DATOS AMARILLOS",IF(D14<40,"ATENCIÓN PRIORITARIA · revisa los subindicadores con menor puntaje",IF(D14<60,"NIVEL BAJO / EN DESARROLLO · existen brechas importantes",IF(D14<80,"NIVEL MEDIO · situación aceptable con áreas de mejora","NIVEL ALTO / FAVORABLE · condiciones sólidas respecto a tus referencias")))) -> NIVEL MEDIO · situación aceptable con áreas de mejora
A17: WEB-02 · PERTINENCIA NORMATIVA
A18: ¿PARA QUÉ SIRVE? Resume qué tan sólido es el entorno de política, regulación, cumplimiento, colaboración y gobernanza.
A20: Código | B20: Subindicador | C20: Dirección | D20: VALOR ACTUAL | E20: MUY MALO | F20: MUY BUENO | G20: PUNTAJE 0–100 | H20: Peso % | I20: Aporte | J20: ¿Qué significa? | K20: Fórmula
A21: PN1 | B21: Políticas estatales | C21: Más es mejor | G21: =IF(OR(D21="",E21="",F21=""),"",IF(E21=F21,"",IF(C21="Más es mejor",MAX(0,MIN(100,(D21-E21)/(F21-E21)*100)),MAX(0,MIN(100,(E21-D21)/(E21-F21)*100))))) | H21: 20 | I21: =IF(OR(G21="",H21=""),"",G21*H21/100) | J21: Más instrumentos vigentes y aplicables fortalecen el entorno. | K21: 'Más es mejor: (Actual−Muy malo)/(Muy bueno−Muy malo)×100 | Menos es mejor: (Muy malo−Actual)/(Muy malo−Muy bueno)×100
A22: PN2 | B22: Madurez regulatoria energética | C22: Más es mejor | G22: =IF(OR(D22="",E22="",F22=""),"",IF(E22=F22,"",IF(C22="Más es mejor",MAX(0,MIN(100,(D22-E22)/(F22-E22)*100)),MAX(0,MIN(100,(E22-D22)/(E22-F22)*100))))) | H22: 20 | I22: =IF(OR(G22="",H22=""),"",G22*H22/100) | J22: Mayor claridad y madurez regulatoria facilita operación/inversión. | K22: 'Más es mejor: (Actual−Muy malo)/(Muy bueno−Muy malo)×100 | Menos es mejor: (Muy malo−Actual)/(Muy malo−Muy bueno)×100
A23: PN3 | B23: Cumplimiento T-MEC | C23: Más es mejor | G23: =IF(OR(D23="",E23="",F23=""),"",IF(E23=F23,"",IF(C23="Más es mejor",MAX(0,MIN(100,(D23-E23)/(F23-E23)*100)),MAX(0,MIN(100,(E23-D23)/(E23-F23)*100))))) | H23: 20 | I23: =IF(OR(G23="",H23=""),"",G23*H23/100) | J23: Mayor cumplimiento representa mejor alineación comercial. | K23: 'Más es mejor: (Actual−Muy malo)/(Muy bueno−Muy malo)×100 | Menos es mejor: (Muy malo−Actual)/(Muy malo−Muy bueno)×100
A24: PN4 | B24: Colaboraciones / proyectos | C24: Más es mejor | G24: =IF(OR(D24="",E24="",F24=""),"",IF(E24=F24,"",IF(C24="Más es mejor",MAX(0,MIN(100,(D24-E24)/(F24-E24)*100)),MAX(0,MIN(100,(E24-D24)/(E24-F24)*100))))) | H24: 20 | I24: =IF(OR(G24="",H24=""),"",G24*H24/100) | J24: Más colaboraciones verificables fortalecen articulación internacional. | K24: 'Más es mejor: (Actual−Muy malo)/(Muy bueno−Muy malo)×100 | Menos es mejor: (Muy malo−Actual)/(Muy malo−Muy bueno)×100
A25: PN5 | B25: Gobernanza educativa | C25: Más es mejor | G25: =IF(OR(D25="",E25="",F25=""),"",IF(E25=F25,"",IF(C25="Más es mejor",MAX(0,MIN(100,(D25-E25)/(F25-E25)*100)),MAX(0,MIN(100,(E25-D25)/(E25-F25)*100))))) | H25: 20 | I25: =IF(OR(G25="",H25=""),"",G25*H25/100) | J25: Más mecanismos activos de coordinación mejoran gobernanza. | K25: 'Más es mejor: (Actual−Muy malo)/(Muy bueno−Muy malo)×100 | Menos es mejor: (Muy malo−Actual)/(Muy malo−Muy bueno)×100
A27: RESULTADO FINAL | D27: =IF(COUNT(G21:G25)=0,"",SUM(I21:I25)/(SUM(H21:H25)/100)) | F27: =IF(D27="","CAPTURA LOS DATOS AMARILLOS",IF(D27<40,"ATENCIÓN PRIORITARIA · revisa los subindicadores con menor puntaje",IF(D27<60,"NIVEL BAJO / EN DESARROLLO · existen brechas importantes",IF(D27<80,"NIVEL MEDIO · situación aceptable con áreas de mejora","NIVEL ALTO / FAVORABLE · condiciones sólidas respecto a tus referencias")))) -> CAPTURA LOS DATOS AMARILLOS
A30: WEB-03 · PERTINENCIA SOCIAL
A31: ¿PARA QUÉ SIRVE? Resume la capacidad del ecosistema para formar, emplear y actualizar talento pertinente.
A33: Código | B33: Subindicador | C33: Dirección | D33: VALOR ACTUAL | E33: MUY MALO | F33: MUY BUENO | G33: PUNTAJE 0–100 | H33: Peso % | I33: Aporte | J33: ¿Qué significa? | K33: Fórmula
A34: PS1 | B34: Ingenieros formados al año | C34: Más es mejor | G34: =IF(OR(D34="",E34="",F34=""),"",IF(E34=F34,"",IF(C34="Más es mejor",MAX(0,MIN(100,(D34-E34)/(F34-E34)*100)),MAX(0,MIN(100,(E34-D34)/(E34-F34)*100))))) | H34: 20 | I34: =IF(OR(G34="",H34=""),"",G34*H34/100) | J34: Mayor oferta de egresados aumenta disponibilidad de talento. | K34: 'Más es mejor: (Actual−Muy malo)/(Muy bueno−Muy malo)×100 | Menos es mejor: (Muy malo−Actual)/(Muy malo−Muy bueno)×100
A35: PS2 | B35: Brecha de talento | C35: Menos es mejor | G35: =IF(OR(D35="",E35="",F35=""),"",IF(E35=F35,"",IF(C35="Más es mejor",MAX(0,MIN(100,(D35-E35)/(F35-E35)*100)),MAX(0,MIN(100,(E35-D35)/(E35-F35)*100))))) | H35: 20 | I35: =IF(OR(G35="",H35=""),"",G35*H35/100) | J35: Una brecha menor indica mejor ajuste entre oferta y demanda de competencias. | K35: 'Más es mejor: (Actual−Muy malo)/(Muy bueno−Muy malo)×100 | Menos es mejor: (Muy malo−Actual)/(Muy malo−Muy bueno)×100
A36: PS3 | B36: Empleabilidad STEM | C36: Más es mejor | G36: =IF(OR(D36="",E36="",F36=""),"",IF(E36=F36,"",IF(C36="Más es mejor",MAX(0,MIN(100,(D36-E36)/(F36-E36)*100)),MAX(0,MIN(100,(E36-D36)/(E36-F36)*100))))) | H36: 20 | I36: =IF(OR(G36="",H36=""),"",G36*H36/100) | J36: Mayor empleabilidad sugiere mejor absorción del talento. | K36: 'Más es mejor: (Actual−Muy malo)/(Muy bueno−Muy malo)×100 | Menos es mejor: (Muy malo−Actual)/(Muy malo−Muy bueno)×100
A37: PS4 | B37: Actualización docente | C37: Más es mejor | G37: =IF(OR(D37="",E37="",F37=""),"",IF(E37=F37,"",IF(C37="Más es mejor",MAX(0,MIN(100,(D37-E37)/(F37-E37)*100)),MAX(0,MIN(100,(E37-D37)/(E37-F37)*100))))) | H37: 20 | I37: =IF(OR(G37="",H37=""),"",G37*H37/100) | J37: Mayor actualización fortalece la capacidad formativa. | K37: 'Más es mejor: (Actual−Muy malo)/(Muy bueno−Muy malo)×100 | Menos es mejor: (Muy malo−Actual)/(Muy malo−Muy bueno)×100
A38: PS5 | B38: Formación especializada | C38: Más es mejor | G38: =IF(OR(D38="",E38="",F38=""),"",IF(E38=F38,"",IF(C38="Más es mejor",MAX(0,MIN(100,(D38-E38)/(F38-E38)*100)),MAX(0,MIN(100,(E38-D38)/(E38-F38)*100))))) | H38: 20 | I38: =IF(OR(G38="",H38=""),"",G38*H38/100) | J38: Más programas pertinentes aumentan oferta especializada. | K38: 'Más es mejor: (Actual−Muy malo)/(Muy bueno−Muy malo)×100 | Menos es mejor: (Muy malo−Actual)/(Muy malo−Muy bueno)×100
A40: RESULTADO FINAL | D40: =IF(COUNT(G34:G38)=0,"",SUM(I34:I38)/(SUM(H34:H38)/100)) | F40: =IF(D40="","CAPTURA LOS DATOS AMARILLOS",IF(D40<40,"ATENCIÓN PRIORITARIA · revisa los subindicadores con menor puntaje",IF(D40<60,"NIVEL BAJO / EN DESARROLLO · existen brechas importantes",IF(D40<80,"NIVEL MEDIO · situación aceptable con áreas de mejora","NIVEL ALTO / FAVORABLE · condiciones sólidas respecto a tus referencias")))) -> CAPTURA LOS DATOS AMARILLOS
A43: WEB-04 · PERTINENCIA TECNOLÓGICA
A44: ¿PARA QUÉ SIRVE? Resume la capacidad efectiva de laboratorios, madurez tecnológica, diseño/pruebas, manufactura y proyectos.
A46: Código | B46: Subindicador | C46: Dirección | D46: VALOR ACTUAL | E46: MUY MALO | F46: MUY BUENO | G46: PUNTAJE 0–100 | H46: Peso % | I46: Aporte | J46: ¿Qué significa? | K46: Fórmula
A47: PT1 | B47: Laboratorios especializados | C47: Más es mejor | G47: =IF(OR(D47="",E47="",F47=""),"",IF(E47=F47,"",IF(C47="Más es mejor",MAX(0,MIN(100,(D47-E47)/(F47-E47)*100)),MAX(0,MIN(100,(E47-D47)/(E47-F47)*100))))) | H47: 20 | I47: =IF(OR(G47="",H47=""),"",G47*H47/100) | J47: Más capacidad operativa de laboratorios fortalece I+D y pruebas. | K47: 'Más es mejor: (Actual−Muy malo)/(Muy bueno−Muy malo)×100 | Menos es mejor: (Muy malo−Actual)/(Muy malo−Muy bueno)×100
A48: PT2 | B48: TRL promedio/mediano | C48: Más es mejor | G48: =IF(OR(D48="",E48="",F48=""),"",IF(E48=F48,"",IF(C48="Más es mejor",MAX(0,MIN(100,(D48-E48)/(F48-E48)*100)),MAX(0,MIN(100,(E48-D48)/(E48-F48)*100))))) | H48: 20 | I48: =IF(OR(G48="",H48=""),"",G48*H48/100) | J48: Mayor TRL implica tecnologías más cercanas a aplicación. | K48: 'Más es mejor: (Actual−Muy malo)/(Muy bueno−Muy malo)×100 | Menos es mejor: (Muy malo−Actual)/(Muy malo−Muy bueno)×100
A49: PT3 | B49: Programas de diseño y pruebas | C49: Más es mejor | G49: =IF(OR(D49="",E49="",F49=""),"",IF(E49=F49,"",IF(C49="Más es mejor",MAX(0,MIN(100,(D49-E49)/(F49-E49)*100)),MAX(0,MIN(100,(E49-D49)/(E49-F49)*100))))) | H49: 20 | I49: =IF(OR(G49="",H49=""),"",G49*H49/100) | J49: Más oferta formal fortalece capacidades de diseño/prueba. | K49: 'Más es mejor: (Actual−Muy malo)/(Muy bueno−Muy malo)×100 | Menos es mejor: (Muy malo−Actual)/(Muy malo−Muy bueno)×100
A50: PT4 | B50: Capacidad EMS/PCBA | C50: Más es mejor | G50: =IF(OR(D50="",E50="",F50=""),"",IF(E50=F50,"",IF(C50="Más es mejor",MAX(0,MIN(100,(D50-E50)/(F50-E50)*100)),MAX(0,MIN(100,(E50-D50)/(E50-F50)*100))))) | H50: 20 | I50: =IF(OR(G50="",H50=""),"",G50*H50/100) | J50: Mayor capacidad instalada fortalece manufactura electrónica. | K50: 'Más es mejor: (Actual−Muy malo)/(Muy bueno−Muy malo)×100 | Menos es mejor: (Muy malo−Actual)/(Muy malo−Muy bueno)×100
A51: PT5 | B51: Proyectos activos | C51: Más es mejor | G51: =IF(OR(D51="",E51="",F51=""),"",IF(E51=F51,"",IF(C51="Más es mejor",MAX(0,MIN(100,(D51-E51)/(F51-E51)*100)),MAX(0,MIN(100,(E51-D51)/(E51-F51)*100))))) | H51: 20 | I51: =IF(OR(G51="",H51=""),"",G51*H51/100) | J51: Más proyectos activos reflejan dinamismo tecnológico. | K51: 'Más es mejor: (Actual−Muy malo)/(Muy bueno−Muy malo)×100 | Menos es mejor: (Muy malo−Actual)/(Muy malo−Muy bueno)×100
A53: RESULTADO FINAL | D53: =IF(COUNT(G47:G51)=0,"",SUM(I47:I51)/(SUM(H47:H51)/100)) | F53: =IF(D53="","CAPTURA LOS DATOS AMARILLOS",IF(D53<40,"ATENCIÓN PRIORITARIA · revisa los subindicadores con menor puntaje",IF(D53<60,"NIVEL BAJO / EN DESARROLLO · existen brechas importantes",IF(D53<80,"NIVEL MEDIO · situación aceptable con áreas de mejora","NIVEL ALTO / FAVORABLE · condiciones sólidas respecto a tus referencias")))) -> CAPTURA LOS DATOS AMARILLOS
A56: WEB-05 · PERTINENCIA ECONÓMICA
A57: ¿PARA QUÉ SIRVE? Resume la escala, crecimiento, articulación productiva y efecto económico del mercado atendible.
...

Sheet RESUMEN
A1: RESUMEN AUTOMÁTICO DE LOS 7 INDICADORES
A3: Indicador web | B3: Resultado | C3: Semáforo | D3: Mensaje | E3: ¿Para qué sirve? | F3: Soporte principal
A4: Pertinencia Sostenible | B4: =CALCULADORA_7!D14 -> 64 | C4: =IF(B4="","Sin datos",IF(B4<40,"ROJO",IF(B4<60,"NARANJA",IF(B4<80,"AMARILLO","VERDE")))) -> AMARILLO | D4: =IF(B4="","Captura los datos en CALCULADORA_7",IF(B4<40,"Atención prioritaria",IF(B4<60,"En desarrollo",IF(B4<80,"Nivel medio / favorable con mejoras","Nivel alto / favorable")))) -> Nivel medio / favorable con mejoras | E4: Resume energía, eficiencia, emisiones y agua. | F4: PSO1–PSO5
A5: Pertinencia Normativa | B5: =CALCULADORA_7!D27 | C5: =IF(B5="","Sin datos",IF(B5<40,"ROJO",IF(B5<60,"NARANJA",IF(B5<80,"AMARILLO","VERDE")))) -> Sin datos | D5: =IF(B5="","Captura los datos en CALCULADORA_7",IF(B5<40,"Atención prioritaria",IF(B5<60,"En desarrollo",IF(B5<80,"Nivel medio / favorable con mejoras","Nivel alto / favorable")))) -> Captura los datos en CALCULADORA_7 | E5: Resume política, regulación, cumplimiento y gobernanza. | F5: PN1–PN5
A6: Pertinencia Social | B6: =CALCULADORA_7!D40 | C6: =IF(B6="","Sin datos",IF(B6<40,"ROJO",IF(B6<60,"NARANJA",IF(B6<80,"AMARILLO","VERDE")))) -> Sin datos | D6: =IF(B6="","Captura los datos en CALCULADORA_7",IF(B6<40,"Atención prioritaria",IF(B6<60,"En desarrollo",IF(B6<80,"Nivel medio / favorable con mejoras","Nivel alto / favorable")))) -> Captura los datos en CALCULADORA_7 | E6: Resume formación, brechas, empleabilidad y actualización del talento. | F6: PS1–PS5
A7: Pertinencia Tecnológica | B7: =CALCULADORA_7!D53 | C7: =IF(B7="","Sin datos",IF(B7<40,"ROJO",IF(B7<60,"NARANJA",IF(B7<80,"AMARILLO","VERDE")))) -> Sin datos | D7: =IF(B7="","Captura los datos en CALCULADORA_7",IF(B7<40,"Atención prioritaria",IF(B7<60,"En desarrollo",IF(B7<80,"Nivel medio / favorable con mejoras","Nivel alto / favorable")))) -> Captura los datos en CALCULADORA_7 | E7: Resume laboratorios, TRL, diseño/pruebas, manufactura y proyectos. | F7: PT1–PT5
A8: Pertinencia Económica | B8: =CALCULADORA_7!D65 | C8: =IF(B8="","Sin datos",IF(B8<40,"ROJO",IF(B8<60,"NARANJA",IF(B8<80,"AMARILLO","VERDE")))) -> Sin datos | D8: =IF(B8="","Captura los datos en CALCULADORA_7",IF(B8<40,"Atención prioritaria",IF(B8<60,"En desarrollo",IF(B8<80,"Nivel medio / favorable con mejoras","Nivel alto / favorable")))) -> Captura los datos en CALCULADORA_7 | E8: Resume tamaño, crecimiento e impacto económico del mercado. | F8: PE1–PE4
A9: SAM 2025 | B9: =IF(CALCULADORA_7!C76="","",CALCULADORA_7!C76&" a "&CALCULADORA_7!E76&" MUSD") | C9: RANGO | D9: Estimación triangulada; no representa ventas observadas. | E9: Dimensiona el mercado atendible de referencia 2025. | F9: PE1 + proxies A–C
A10: SAM 2030 | B10: =IF(CALCULADORA_7!C87="","",CALCULADORA_7!C87&" a "&CALCULADORA_7!E87&" MUSD") | C10: PROYECCIÓN | D10: Escenario proyectado; debe leerse con sus supuestos. | E10: Dimensiona el mercado atendible esperado hacia 2030. | F10: PE1–PE2 + proxies

Sheet MAPA_39
A1: TUS 39 INDICADORES · ¿PARA QUÉ SIRVEN Y DÓNDE QUEDARON EN LOS 7 DE LA WEB?
A3: Código | B3: Indicador | C3: ¿Para qué sirve? | D3: Dimensión | E3: Relación con web | F3: Tarjeta web
A4: PE1 | B4: Tamaño del SAM regional | C4: Dimensionar el mercado atendible regional. | D4: Económica | E4: Directa | F4: Económica / SAM
A5: PE2 | B5: Crecimiento proyectado del SAM | C5: Medir ritmo esperado de crecimiento. | D5: Económica | E5: Directa | F5: Económica / SAM 2030
A6: PE3 | B6: Encadenamientos industriales | C6: Medir integración productiva regional. | D6: Económica | E6: Directa | F6: Económica
A7: PE4 | B7: Multiplicador económico | C7: Estimar efecto económico de la inversión. | D7: Económica | E7: Directa | F7: Económica
A8: DM1 | B8: Demanda inducida automotriz | C8: Estimar demanda sector automotriz. | D8: Demanda | E8: Indirecta | F8: Económica / SAM
A9: DM2 | B9: Demanda inducida aeroespacial | C9: Estimar demanda sector aeroespacial. | D9: Demanda | E9: Indirecta | F9: Económica / SAM
A10: DM3 | B10: Demanda inducida centros de datos | C10: Estimar demanda de centros de datos. | D10: Demanda | E10: Indirecta | F10: Económica / SAM
A11: DM4 | B11: Concentración de sectores estratégicos | C11: Medir dependencia de pocos sectores. | D11: Demanda | E11: No visible directa | F11: Sin tarjeta propia
A12: DM5 | B12: Elasticidad del crecimiento sectorial | C12: Medir respuesta de capacidad ante demanda. | D12: Demanda | E12: No visible directa | F12: Sin tarjeta propia
A13: PT1 | B13: Laboratorios especializados existentes | C13: Medir capacidad de laboratorios/equipos. | D13: Tecnológica | E13: Directa | F13: Tecnológica
A14: PT2 | B14: Nivel de madurez tecnológica (TRL) | C14: Medir madurez tecnológica. | D14: Tecnológica | E14: Directa | F14: Tecnológica
... A42: PI5 | B42: Pruebas y prototipos | C42: Medir capacidades de prueba/prototipado. | D42: Infraestructural | E42: No visible directa | F42: Sin tarjeta propia
